{
  "timestamp": "20250629_091851",
  "duration_seconds": 30.11570119857788,
  "return_code": 1,
  "stdout": "============================= test session starts ==============================\nplatform darwin -- Python 3.10.14, pytest-8.4.1, pluggy-1.6.0 -- /Volumes/T7/arkalia-luna-venv/bin/python\ncachedir: .pytest_cache\nbenchmark: 5.1.0 (defaults: timer=time.perf_counter disable_gc=False min_rounds=5 min_time=0.000005 max_time=1.0 calibration_precision=10 warmup=False warmup_iterations=100000)\nrootdir: /Volumes/T7/devstation/cursor/arkalia-luna-pro\nconfigfile: pytest.ini\ntestpaths: tests/unit, tests/integration, tests/performance\nplugins: anyio-4.9.0, cov-6.2.1, asyncio-1.0.0, benchmark-5.1.0\nasyncio: mode=strict, asyncio_default_fixture_loop_scope=None, asyncio_default_test_loop_scope=function\ncollecting ... collected 379 items / 374 deselected / 5 selected\n\ntests/performance/test_chat_response_time.py::test_chat_response_time_under_2s FAILED\ntests/performance/test_zeroia_performance.py::test_zeroia_decision_time_under_2s \ud83d\udd04 ZeroIA decided: monitor (confidence=0.5, health=1.00)\n[ZeroIA] CPU usage: 45.2% \u2192 decision=monitor (score=0.5)\n[ZeroIA] Error Recovery triggered for: DecisionIntegrityError\n\u2705 ZeroIA d\u00e9cision en 0.002s (objectif < 2.0s)\n\ud83d\udcca M\u00e9moire utilis\u00e9e : 0.9 MB\nPASSED\ntests/performance/test_zeroia_performance.py::test_circuit_breaker_latency_under_10ms \u2705 Circuit Breaker - Latence moyenne : 0.03ms\n\ud83d\udcca Min: 0.03ms | Max: 0.07ms\nPASSED\ntests/performance/test_zeroia_performance.py::test_event_store_write_performance SKIPPED\ntests/performance/test_zeroia_performance.py::test_performance_regression_detection \ud83d\udcca Benchmark zeroia_decision_time: seuil 2.0\n\ud83d\udcca Benchmark circuit_breaker_latency: seuil 10.0\n\ud83d\udcca Benchmark event_store_write: seuil 50.0\n\ud83d\udcca Benchmark orchestrator_throughput: seuil 10.0\n\ud83d\udcca Benchmark memory_growth: seuil 100.0\n\u2705 Seuils de performance valid\u00e9s\nPASSED\nWARNING: Failed to generate report: No data to report.\n\n\n\n=================================== FAILURES ===================================\n_______________________ test_chat_response_time_under_2s _______________________\ntests/performance/test_chat_response_time.py:36: in test_chat_response_time_under_2s\n    assert (\nE   AssertionError: \u274c R\u00e9ponse trop lente : 13.37s (limite : 4.5s)\nE   assert 13.371248960494995 < 4.5\n================================ tests coverage ================================\n______________ coverage: platform darwin, python 3.10.14-final-0 _______________\n\n=========================== short test summary info ============================\nSKIPPED [1] tests/performance/test_zeroia_performance.py:182: Test obsol\u00e8te - d\u00e9pend d'EventStore incompatible\nFAILED tests/performance/test_chat_response_time.py::test_chat_response_time_under_2s\n=========== 1 failed, 3 passed, 1 skipped, 374 deselected in 29.60s ============\n",
  "stderr": "/Volumes/T7/arkalia-luna-venv/lib/python3.10/site-packages/coverage/control.py:915: CoverageWarning: No data was collected. (no-data-collected)\n  self._warn(\"No data was collected.\", slug=\"no-data-collected\")\n/Volumes/T7/arkalia-luna-venv/lib/python3.10/site-packages/pytest_cov/plugin.py:358: CovReportWarning: Failed to generate report: No data to report.\n\n  warnings.warn(CovReportWarning(message), stacklevel=1)\n",
  "environment": {
    "python_version": "3.10.14 (main, Jun 17 2025, 15:39:18) [Clang 17.0.0 (clang-1700.0.13.5)]",
    "os": "posix",
    "platform": "darwin"
  }
}