# ðŸ§ª Tests pour main_loop et le point d'entrÃ©e de ZeroIA
from io import StringIO
from unittest.mock import patch

import pytest

from modules.zeroia.reason_loop import main_loop
from tests.common.helpers import ensure_test_toml

ensure_test_toml()


def test_main_loop_success():
    """ðŸ§  Test de main_loop avec un appel rÃ©ussi de reason_loop"""
    with patch("modules.zeroia.reason_loop.reason_loop") as mock_reason_loop:
        mock_reason_loop.return_value = ("reduce_load", 0.75)

        # Capture la sortie standard
        captured_output = StringIO()
        with patch("sys.stdout", captured_output):
            main_loop()

        # VÃ©rifie que reason_loop a Ã©tÃ© appelÃ©
        mock_reason_loop.assert_called_once()

        # VÃ©rifie la sortie
        output = captured_output.getvalue()
        assert "[ZeroIA] loop started" in output


def test_main_loop_with_exception():
    """ðŸ§  Test de main_loop quand reason_loop lÃ¨ve une exception"""
    with patch("modules.zeroia.reason_loop.reason_loop") as mock_reason_loop:
        mock_reason_loop.side_effect = ValueError("Test error")

        with patch("modules.zeroia.reason_loop.logger") as mock_logger:
            captured_output = StringIO()
            with patch("sys.stdout", captured_output):
                main_loop()

            # VÃ©rifie que l'exception a Ã©tÃ© loggÃ©e
            mock_logger.exception.assert_called_once()

            # VÃ©rifie la sortie d'erreur
            output = captured_output.getvalue()
            assert "ðŸš¨ ERREUR dans reason_loop()" in output
            assert "Test error" in output


def test_main_loop_with_keyboard_interrupt():
    """ðŸ§  Test de main_loop avec KeyboardInterrupt (qui ne devrait pas Ãªtre capturÃ©e)"""
    with patch("modules.zeroia.reason_loop.reason_loop") as mock_reason_loop:
        mock_reason_loop.side_effect = KeyboardInterrupt()

        # KeyboardInterrupt ne devrait pas Ãªtre capturÃ©e par main_loop
        with pytest.raises(KeyboardInterrupt):
            main_loop()


def test_main_loop_with_system_exit():
    """ðŸ§  Test de main_loop avec SystemExit (qui ne devrait pas Ãªtre capturÃ©e)"""
    with patch("modules.zeroia.reason_loop.reason_loop") as mock_reason_loop:
        mock_reason_loop.side_effect = SystemExit(1)

        # SystemExit ne devrait pas Ãªtre capturÃ©e par main_loop
        with pytest.raises(SystemExit):
            main_loop()


def test_main_loop_output_formatting():
    """ðŸ§  Test du formatage de sortie de main_loop"""
    with patch("modules.zeroia.reason_loop.reason_loop") as mock_reason_loop:
        mock_reason_loop.return_value = ("monitor", 0.6)

        captured_output = StringIO()
        with patch("sys.stdout", captured_output):
            main_loop()

        output = captured_output.getvalue()
        assert "[ZeroIA] loop started" in output
        # VÃ©rifie que flush=True est utilisÃ© (pas de test direct possible)


def test_main_loop_multiple_calls():
    """ðŸ§  Test d'appels multiples Ã  main_loop"""
    with patch("modules.zeroia.reason_loop.reason_loop") as mock_reason_loop:
        mock_reason_loop.return_value = ("normal", 0.4)

        # Appelle main_loop plusieurs fois
        for i in range(3):
            main_loop()

        # VÃ©rifie que reason_loop a Ã©tÃ© appelÃ© 3 fois
        assert mock_reason_loop.call_count == 3


def test_main_loop_with_different_exceptions():
    """ðŸ§  Test de main_loop avec diffÃ©rents types d'exceptions"""
    exceptions_to_test = [
        ValueError("Value error"),
        RuntimeError("Runtime error"),
        FileNotFoundError("File not found"),
        PermissionError("Permission denied"),
        ConnectionError("Connection failed"),
    ]

    for exception in exceptions_to_test:
        with patch("modules.zeroia.reason_loop.reason_loop") as mock_reason_loop:
            mock_reason_loop.side_effect = exception

            with patch("modules.zeroia.reason_loop.logger") as mock_logger:
                captured_output = StringIO()
                with patch("sys.stdout", captured_output):
                    main_loop()

                # VÃ©rifie que l'exception a Ã©tÃ© loggÃ©e
                mock_logger.exception.assert_called_once_with(exception)

                # VÃ©rifie le message d'erreur
                output = captured_output.getvalue()
                assert "ðŸš¨ ERREUR dans reason_loop()" in output
                assert str(exception) in output


def test_main_loop_logger_configuration():
    """ðŸ§  Test que main_loop utilise le bon logger"""
    with patch("modules.zeroia.reason_loop.reason_loop") as mock_reason_loop:
        mock_reason_loop.side_effect = Exception("Test exception")

        with patch("modules.zeroia.reason_loop.logger") as mock_logger:
            main_loop()

            # VÃ©rifie que logger.exception a Ã©tÃ© appelÃ© avec l'exception
            mock_logger.exception.assert_called_once()
            args, _ = mock_logger.exception.call_args
            assert isinstance(args[0], Exception)
            assert str(args[0]) == "Test exception"


def test_main_loop_stdout_flushing():
    """ðŸ§  Test que main_loop utilise flush=True pour l'affichage immÃ©diat"""
    with patch("modules.zeroia.reason_loop.reason_loop") as mock_reason_loop:
        mock_reason_loop.return_value = ("reduce_load", 0.75)

        # Mock print pour vÃ©rifier les appels avec flush=True
        with patch("builtins.print") as mock_print:
            main_loop()

            # VÃ©rifie que print a Ã©tÃ© appelÃ© avec flush=True
            mock_print.assert_called_with("[ZeroIA] loop started", flush=True)


def test_main_loop_reason_loop_call():
    """ðŸ§  Test que main_loop appelle reason_loop sans arguments"""
    with patch("modules.zeroia.reason_loop.reason_loop") as mock_reason_loop:
        mock_reason_loop.return_value = ("normal", 0.4)

        main_loop()

        # VÃ©rifie que reason_loop est appelÃ© sans arguments
        mock_reason_loop.assert_called_once_with()


def test_main_loop_exception_handling_preserves_original_exception():
    """ðŸ§  Test que le handling d'exception prÃ©serve l'exception orig."""
    original_exception = ValueError("Original error message")

    with patch("modules.zeroia.reason_loop.reason_loop") as mock_reason_loop:
        mock_reason_loop.side_effect = original_exception

        with patch("modules.zeroia.reason_loop.logger") as mock_logger:
            main_loop()

            # VÃ©rifie que l'exception originale est passÃ©e au logger
            mock_logger.exception.assert_called_once_with(original_exception)
