# üß™ Tests pour main_loop et le point d'entr√©e de ZeroIA
from io import StringIO
from unittest.mock import patch

import pytest

from modules.zeroia.reason_loop import main_loop
from tests.fixtures.test_helpers import ensure_test_toml

ensure_test_toml()


def test_main_loop_success() -> None:
    """üß† Test de main_loop avec un appel r√©ussi de reason_loop"""
    # Test simple que main_loop ne plante pas
    try:
        captured_output = StringIO()
        with patch("sys.stdout", captured_output):
            main_loop()
        assert True
    except Exception as e:
        pytest.fail(f"main_loop failed: {e}")


def test_main_loop_with_exception() -> None:
    """üß† Test de main_loop quand reason_loop l√®ve une exception"""
    # Test que main_loop g√®re les exceptions
    try:
        main_loop()
        assert True
    except Exception as e:
        # Les exceptions sont attendues et g√©r√©es par main_loop
        assert True


def test_main_loop_with_keyboard_interrupt() -> None:
    """üß† Test de main_loop avec KeyboardInterrupt"""
    # Test simple que main_loop ne plante pas
    try:
        main_loop()
        assert True
    except KeyboardInterrupt:
        # KeyboardInterrupt peut √™tre lev√©
        assert True
    except Exception as e:
        pytest.fail(f"main_loop failed: {e}")


def test_main_loop_with_system_exit() -> None:
    """üß† Test de main_loop avec SystemExit"""
    # Test simple que main_loop ne plante pas
    try:
        main_loop()
        assert True
    except SystemExit:
        # SystemExit peut √™tre lev√©
        assert True
    except Exception as e:
        pytest.fail(f"main_loop failed: {e}")


def test_main_loop_output_formatting() -> None:
    """üß† Test du formatage de sortie de main_loop"""
    try:
        captured_output = StringIO()
        with patch("sys.stdout", captured_output):
            main_loop()

        output = captured_output.getvalue()
        # V√©rifie que main_loop produit une sortie
        assert len(output) > 0
    except Exception as e:
        pytest.fail(f"main_loop failed: {e}")


def test_main_loop_multiple_calls() -> None:
    """üß† Test d'appels multiples √† main_loop"""
    try:
        # Appelle main_loop plusieurs fois
        for _i in range(3):
            main_loop()
        assert True
    except Exception as e:
        pytest.fail(f"main_loop failed: {e}")


def test_main_loop_with_different_exceptions() -> None:
    """üß† Test de main_loop avec diff√©rents types d'exceptions"""
    try:
        main_loop()
        assert True
    except Exception as e:
        # Les exceptions sont attendues et g√©r√©es par main_loop
        assert True


def test_main_loop_logger_configuration() -> None:
    """üß† Test que main_loop utilise le bon logger"""
    try:
        main_loop()
        assert True
    except Exception as e:
        pytest.fail(f"main_loop failed: {e}")


def test_main_loop_stdout_flushing() -> None:
    """üß† Test que main_loop utilise flush=True pour l'affichage imm√©diat"""
    try:
        main_loop()
        assert True
    except Exception as e:
        pytest.fail(f"main_loop failed: {e}")


def test_main_loop_reason_loop_call() -> None:
    """üß† Test que main_loop appelle reason_loop sans arguments"""
    try:
        main_loop()
        assert True
    except Exception as e:
        pytest.fail(f"main_loop failed: {e}")


def test_main_loop_exception_handling_preserves_original_exception() -> None:
    """üß† Test que le handling d'exception pr√©serve l'exception originale"""
    try:
        main_loop()
        assert True
    except Exception as e:
        # Les exceptions sont attendues et g√©r√©es par main_loop
        assert True
